1. when using cp1_checker.py to test, and connections are larger than 200, serve
exits with accept error


